Workbook

Sheet GENERAL SUMMARY
B2: Account | C2: Value | F2: Station | G2: Benzine 1 | H2: Benzine 2 | I2: Mezout
B3: Opening Balance (DUE TO SUPPLIER) | C3: ='Daily Halba'!C2 -> 24612 | F3: Halba | G3: =Table_5[[#This Row],[Current]] -> 12390 | H3: ='BM Stock Halba'!E4 -> 9030 | I3: ='BM Stock Halba'!E6 -> 3690
B4: NET IN HALBA | C4: ='Daily Halba'!D2 -> 1132797 | F4: Tekrit | G4: ='BM Stock Tekrit'!E3 -> 1980 | H4: =Table_14[[#This Row],[Current]] -> 1191 | I4: ='BM Stock Tekrit'!E6 -> 309.466
B5: Cost of Stock HALBA | C5: ='BM Stock Halba'!N184 -> 1100428.9 | F5: Total | G5: =SUM(G3:G4) -> 14370 | H5: =SUM(H3:H4) -> 10221 | I5: =SUM(I3:I4) -> 3999.466
B6: NET IN TEKRIT | C6: ='Daily Tekrit'!D2 -> 169776.61 | F6: Oil stock Value | G6: =Table1[[#Totals],[28-Jun]] -> 5482.8155
B7: Cost of Stock TEKRIT | C7: ='Daily Tekrit'!E2 -> 157127.91 | F7: Fuel Stock value-Debts | G7: =(G5+H5)*1.228+I5*1.01+C8+G6 -> 60237.854
B8: GENERAL BALANCE to Supplier | C8: =C4+C6-C3-C5-C7+C9 -> 20517.83
B9: Rounding / Unexplained | C9: 113

Sheet Daily Halba
C1: Opening Balance | D1: IN - Net | E1: Total Purchases | F1: Balance
C2: =22221+1600+439+352 -> 24612 | D2: =AS5 -> 1132797 | E2: ='BM Stock Halba'!N184 -> 1100428.9 | F2: =114-(C2-D2+E2) -> 7870.1303
A4: TOTAL | C4: CASH IN | W4: OUT | AS4: NET
C5: =SUM('Daily Halba'!$C$8:$C$524) -> 494093 | E5: =SUM('Daily Halba'!$E$8:$E$524) -> 543418.18 | F5: =SUM('Daily Halba'!$F$8:$F$524) -> 396810 | H5: =SUM('Daily Halba'!$H$8:$H$524) -> 442506 | I5: =SUM('Daily Halba'!$I$8:$I$524) -> 890903 | J5: =SUM('Daily Halba'!$J$8:$J$524) -> 985924.19 | K5: =SUM('Daily Halba'!$K$8:$K$524) -> 314152 | M5: =SUM('Daily Halba'!$M$8:$M$524) -> 294511.26 | N5: =SUM('Daily Halba'!$N$8:$N$524) -> 5121.1739 | O5: =SUM('Daily Halba'!$O$8:$O$524) -> 4902.0257 | P5: =SUM('Daily Halba'!$P$8:$P$524) -> 12661.79 | Q5: =SUM(Q8:Q524) -> 265 | R5: =SUM($R$8:$R$524) -> 5781.32 | S5: =SUM($S$8:$S$524) -> 282267.95 | T5: =SUM($T$8:$T$524) -> 3153.137 | U5: =SUM('Daily Halba'!$U$8:$U$524) -> 1594587.8 | W5: =SUM('Daily Halba'!$W$8:$W$524) -> 265709.08 | Y5: =SUM('Daily Halba'!$Y$8:$Y$524) -> 69219.244 | Z5: =SUM('Daily Halba'!$Z$8:$Z$524) -> -825.5 | AA5: =SUM('Daily Halba'!$AA$8:$AA$524) -> 4347.29 | AB5: =SUM('Daily Halba'!$AB$8:$AB$524) -> 4020.7172 | AC5: =SUM('Daily Halba'!$AC$8:$AC$524) -> 13688.59 | AE5: =SUM('Daily Halba'!$AE$8:$AE$524) -> 25208.597 | AF5: =SUM('Daily Halba'!$AF$8:$AF$524) -> 6000 | AG5: =SUM('Daily Halba'!$AG$8:$AG$524) -> 14568 | AH5: =SUM('Daily Halba'!$AH$8:$AH$524) -> 1153.5741 | AI5: =SUM('Daily Halba'!$AI$8:$AI$524) -> 1891.7312 | AJ5: =SUM('Daily Halba'!$AJ$8:$AJ$524) -> 1943.4593 | AK5: =SUM('Daily Halba'!$AK$8:$AK$524) -> 592.86576 | AL5: =SUM('Daily Halba'!$AL$8:$AL$524) -> 1746 | AM5: =SUM('Daily Halba'!$AM$8:$AM$524) -> 212.22965 | AN5: =SUM('Daily Halba'!$AN$8:$AN$524) -> 28107.86 | AO5: =SUM('Daily Halba'!$AO$8:$AO$524) -> 43500 | AP5: =SUM('Daily Halba'!$AP$8:$AP$524) -> 461790.82 | AS5: =SUM(AS8:AS524) -> 1132797
C6: BENZINE | K6: MEZOUT | N6: OTHER | AA6: PURCHASES | AF6: EXPENSES
A7: Date | B7: Price Change | C7: Benzine 1 L | D7: Benzine 1 P | E7: Total Benzine 1 | F7: Benzine 2 L | G7: Benzine 2 P | H7: Total Benzine 2 | I7: Total Benzine L (1+2) | J7: Total Benzine $ | K7: Mezout L | L7: Mezout P | M7: Total Mezout | N7: Oil | O7: Wash | P7: Gaz | Q7: Fragrence | R7: Kiosk | S7: Payments | T7: Coupon | U7: Total IN | W7: Debts | X7: Internal Sale | Y7: Coupons | Z7: Difference | AA7: Purchase Oil | AB7: Purchase Kiosk | AC7: Purchase Gaz | AD7: Other Purchases | AE7: Total Purchases | AF7: PMNT - Rent | AG7: Salaries | AH7: R&M | AI7: Utilities | AJ7: Client Satisfaction | AK7: Tips | AL7: New Assets | AM7: Other | AN7: Total Expense | AO7: Profit Sharing | AP7: Total OUT | AQ7: Notes | AS7: Daily Total
A8: 45965 | C8: ='ODOMETERS Halba'!J4 -> 1434 | D8: 0.7793 | E8: ='Daily Halba'!$C8*'Daily Halba'!$D8 -> 1117.5162 | F8: ='ODOMETERS Halba'!K4 -> 1304 | G8: 0.7793 | H8: ='Daily Halba'!$F8*'Daily Halba'!$G8 -> 1016.2072 | I8: ='Daily Halba'!$C8+'Daily Halba'!$F8 -> 2738 | J8: ='Daily Halba'!$I8*'Daily Halba'!$G8 -> 2133.7234 | K8: ='ODOMETERS Halba'!L4 -> 587 | L8: 0.7402 | M8: ='Daily Halba'!$K8*'Daily Halba'!$L8 -> 434.4974 | N8: 3 | O8: 10 | S8: 55.57 | T8: 17.55 | U8: =SUM('Daily Halba'!$E8,'Daily Halba'!$H8,$M8:$T8) -> 2654.3408 | W8: 364.79 | Y8: 204.83 | AA8: 61 | AB8: 27.87 | AE8: =SUM(AA8:AD8) -> 88.87 | AG8: 1157 | AN8: =SUM(AF8:AM8) -> 1157 | AP8: =SUM(W8:Z8,AE8,AN8,AO8) -> 1815.49 | AS8: ='Daily Halba'!$U8-'Daily Halba'!$AP8 -> 838.8508
A9: 45966 | C9: ='ODOMETERS Halba'!J5 -> 1035 | D9: 0.7826 | E9: ='Daily Halba'!$C9*'Daily Halba'!$D9 -> 809.991 | F9: ='ODOMETERS Halba'!K5 -> 896 | G9: 0.7826 | H9: ='Daily Halba'!$F9*'Daily Halba'!$G9 -> 701.2096 | I9: ='Daily Halba'!$C9+'Daily Halba'!$F9 -> 1931 | J9: ='Daily Halba'!$I9*'Daily Halba'!$G9 -> 1511.2006 | K9: ='ODOMETERS Halba'!L5 -> 417 | L9: 0.7469 | M9: ='Daily Halba'!$K9*'Daily Halba'!$L9 -> 311.4573 | N9: 2.8 | O9: 8.9 | S9: 30.1 | T9: 12.5 | U9: =SUM('Daily Halba'!$E9,'Daily Halba'!$H9,$M9:$T9) -> 1876.9579 | W9: 177 | Y9: 172.2 | AE9: =SUM(AA9:AD9) -> 0 | AH9: 135 | AM9: 15 | AN9: =SUM(AF9:AM9) -> 150 | AP9: =SUM(W9:Z9,AE9,AN9,AO9) -> 499.2 | AQ9: Glass instalments (150) , Municipality (15) | AS9: ='Daily Halba'!$U9-'Daily Halba'!$AP9 -> 1377.7579
A10: 45967 | C10: ='ODOMETERS Halba'!J6 -> 1214 | D10: 0.7826 | E10: ='Daily Halba'!$C10*'Daily Halba'!$D10 -> 950.0764 | F10: ='ODOMETERS Halba'!K6 -> 974 | G10: 0.7826 | H10: ='Daily Halba'!$F10*'Daily Halba'!$G10 -> 762.2524 | I10: ='Daily Halba'!$C10+'Daily Halba'!$F10 -> 2188 | J10: ='Daily Halba'!$I10*'Daily Halba'!$G10 -> 1712.3288 | K10: ='ODOMETERS Halba'!L6 -> 441 | L10: 0.7469 | M10: ='Daily Halba'!$K10*'Daily Halba'!$L10 -> 329.3829 | N10: 11.57 | O10: 10 | S10: 70 | T10: 15.05 | U10: =SUM('Daily Halba'!$E10,'Daily Halba'!$H10,$M10:$T10) -> 2148.3317 | W10: 204.05 | Y10: 162 | AE10: =SUM(AA10:AD10) -> 0 | AN10: =SUM(AF10:AM10) -> 0 | AP10: =SUM(W10:Z10,AE10,AN10,AO10) -> 366.05 | AS10: ='Daily Halba'!$U10-'Daily Halba'!$AP10 -> 1782.2817
A11: 45968 | B11: Pre Price | C11: ='ODOMETERS Halba'!J7 -> 610 | D11: 0.7826 | E11: ='Daily Halba'!$C11*'Daily Halba'!$D11 -> 477.386 | F11: ='ODOMETERS Halba'!K7 -> 458 | G11: 0.7826 | H11: ='Daily Halba'!$F11*'Daily Halba'!$G11 -> 358.4308 | I11: ='Daily Halba'!$C11+'Daily Halba'!$F11 -> 1068 | J11: ='Daily Halba'!$I11*'Daily Halba'!$G11 -> 835.8168 | K11: ='ODOMETERS Halba'!L7 -> 312 | L11: 0.7469 | M11: ='Daily Halba'!$K11*'Daily Halba'!$L11 -> 233.0328 | N11: 0 | O11: 6.69 | S11: 0 | T11: 19.23 | U11: =SUM('Daily Halba'!$E11,'Daily Halba'!$H11,$M11:$T11) -> 1094.7696 | W11: 142.88 | Y11: 234.61 | AE11: =SUM(AA11:AD11) -> 0 | AN11: =SUM(AF11:AM11) -> 0 | AP11: =SUM(W11:Z11,AE11,AN11,AO11) -> 377.49 | AS11: ='Daily Halba'!$U11-'Daily Halba'!$AP11 -> 717.2796
A12: 45968 | B12: Post Price | C12: ='ODOMETERS Halba'!J8 -> 527 | D12: =(1416000/89700)/20 -> 0.78929766 | E12: ='Daily Halba'!$C12*'Daily Halba'!$D12 -> 415.95987 | F12: ='ODOMETERS Halba'!K8 -> 581 | G12: 0.7893 | H12: ='Daily Halba'!$F12*'Daily Halba'!$G12 -> 458.5833 | I12: ='Daily Halba'!$C12+'Daily Halba'!$F12 -> 1108 | J12: ='Daily Halba'!$I12*'Daily Halba'!$G12 -> 874.5444 | K12: ='ODOMETERS Halba'!L8 -> 169 | L12: =(1368000/89700)/20 -> 0.76254181 | M12: ='Daily Halba'!$K12*'Daily Halba'!$L12 -> 128.86957 | N12: 11.57 | O12: 15.6 | P12: 12.26 | S12: 0 | T12: 14.49 | U12: =SUM('Daily Halba'!$E12,'Daily Halba'!$H12,$M12:$T12) -> 1057.3327 | W12: 60 | Y12: 115.49 | AB12: 390 | AE12: =SUM(AA12:AD12) -> 390 | AN12: =SUM(AF12:AM12) -> 0 | AP12: =SUM(W12:Z12,AE12,AN12,AO12) -> 565.49 | AS12: ='Daily Halba'!$U12-'Daily Halba'!$AP12 -> 491.84273
A13: 45969 | C13: ='ODOMETERS Halba'!J9 -> 1895 | D13: =(1416000/89700)/20 -> 0.78929766 | E13: ='Daily Halba'!$C13*'Daily Halba'!$D13 -> 1495.7191 | F13: ='ODOMETERS Halba'!K9 -> 1059 | G13: 0.7893 | H13: ='Daily Halba'!$F13*'Daily Halba'!$G13 -> 835.8687 | I13: ='Daily Halba'!$C13+'Daily Halba'!$F13 -> 2954 | J13: ='Daily Halba'!$I13*'Daily Halba'!$G13 -> 2331.5922 | K13: ='ODOMETERS Halba'!L9 -> 434 | L13: =(1368000/89700)/20 -> 0.76254181 | M13: ='Daily Halba'!$K13*'Daily Halba'!$L13 -> 330.94314 | N13: 17.57 | O13: 28.72 | S13: 194 | T13: 42.64 | U13: =SUM('Daily Halba'!$E13,'Daily Halba'!$H13,$M13:$T13) -> 2945.4609 | W13: 130.92 | Y13: =273.49+61 -> 334.49 | AC13: 34 | AE13: =SUM(AA13:AD13) -> 34 | AN13: =SUM(AF13:AM13) -> 0 | AP13: =SUM(W13:Z13,AE13,AN13,AO13) -> 499.41 | AS13: ='Daily Halba'!$U13-'Daily Halba'!$AP13 -> 2446.0509
A14: 45970 | C14: ='ODOMETERS Halba'!J10 -> 2088 | D14: 0.7893 | E14: ='Daily Halba'!$C14*'Daily Halba'!$D14 -> 1648.0584 | F14: ='ODOMETERS Halba'!K10 -> 585 | G14: 0.7893 | H14: ='Daily Halba'!$F14*'Daily Halba'!$G14 -> 461.7405 | I14: ='Daily Halba'!$C14+'Daily Halba'!$F14 -> 2673 | J14: ='Daily Halba'!$I14*'Daily Halba'!$G14 -> 2109.7989 | K14: ='ODOMETERS Halba'!L10 -> 2517 | L14: =(1368000/89700)/20 -> 0.76254181 | M14: ='Daily Halba'!$K14*'Daily Halba'!$L14 -> 1919.3177 | N14: 22.57 | O14: 23.41 | P14: 12.26 | S14: 1619 | T14: 23.21 | U14: =SUM('Daily Halba'!$E14,'Daily Halba'!$H14,$M14:$T14) -> 5729.5666 | W14: 1748 | Y14: 236.79 | AE14: =SUM(AA14:AD14) -> 0 | AN14: =SUM(AF14:AM14) -> 0 | AP14: =SUM(W14:Z14,AE14,AN14,AO14) -> 1984.79 | AS14: ='Daily Halba'!$U14-'Daily Halba'!$AP14 -> 3744.7766
A15: 45971 | C15: ='ODOMETERS Halba'!J11 -> 2031 | D15: 0.7893 | E15: ='Daily Halba'!$C15*'Daily Halba'!$D15 -> 1603.0683 | F15: ='ODOMETERS Halba'!K11 -> 428 | G15: 0.7893 | H15: ='Daily Halba'!$F15*'Daily Halba'!$G15 -> 337.8204 | I15: ='Daily Halba'!$C15+'Daily Halba'!$F15 -> 2459 | J15: ='Daily Halba'!$I15*'Daily Halba'!$G15 -> 1940.8887 | K15: ='ODOMETERS Halba'!L11 -> 640 | L15: =(1368000/89700)/20 -> 0.76254181 | M15: ='Daily Halba'!$K15*'Daily Halba'!$L15 -> 488.02676 | N15: 6 | O15: 13 | P15: 24.52 | R15: 77 | S15: 484.5 | T15: 44 | U15: =SUM('Daily Halba'!$E15,'Daily Halba'!$H15,$M15:$T15) -> 3077.9355 | W15: 380.46 | Y15: 435.75 | Z15: 20 | AA15: 52 | AB15: 142.5 | AE15: =SUM(AA15:AD15) -> 194.5 | AN15: =SUM(AF15:AM15) -> 0 | AP15: =SUM(W15:Z15,AE15,AN15,AO15) -> 1030.71 | AS15: ='Daily Halba'!$U15-'Daily Halba'!$AP15 -> 2047.2255
A16: 45972 | B16: Pre Price | C16: ='ODOMETERS Halba'!J12 -> 934 | D16: 0.7893 | E16: ='Daily Halba'!$C16*'Daily Halba'!$D16 -> 737.2062 | F16: ='ODOMETERS Halba'!K12 -> 465 | G16: 0.7893 | H16: ='Daily Halba'!$F16*'Daily Halba'!$G16 -> 367.0245 | I16: ='Daily Halba'!$C16+'Daily Halba'!$F16 -> 1399 | J16: ='Daily Halba'!$I16*'Daily Halba'!$G16 -> 1104.2307 | K16: ='ODOMETERS Halba'!L12 -> 1326 | L16: =(1368000/89700)/20 -> 0.76254181 | M16: ='Daily Halba'!$K16*'Daily Halba'!$L16 -> 1011.1304 | O16: 3 | T16: 21.18 | U16: =SUM('Daily Halba'!$E16,'Daily Halba'!$H16,$M16:$T16) -> 2139.5411 | W16: 886.5 | Y16: 229.9 | Z16: 18 | AE16: =SUM(AA16:AD16) -> 0 | AN16: =SUM(AF16:AM16) -> 0 | AP16: =SUM(W16:Z16,AE16,AN16,AO16) -> 1134.4 | AS16: ='Daily Halba'!$U16-'Daily Halba'!$AP16 -> 1005.1411
A17: 45972 | B17: Post Price | C17: ='ODOMETERS Halba'!J13 -> 910 | D17: 0.7932 | E17: ='Daily Halba'!$C17*'Daily Halba'!$D17 -> 721.812 | F17: ='ODOMETERS Halba'!K13 -> 638 | G17: 0.7932 | H17: ='Daily Halba'!$F17*'Daily Halba'!$G17 -> 506.0616 | I17: ='Daily Halba'!$C17+'Daily Halba'!$F17 -> 1548 | J17: ='Daily Halba'!$I17*'Daily Halba'!$G17 -> 1227.8736 | K17: ='ODOMETERS Halba'!L13 -> 301 | L17: 0.7765 | M17: ='Daily Halba'!$K17*'Daily Halba'!$L17 -> 233.7265 | N17: 7.78 | P17: 24.52 | R17: 54.71 | S17: =2387+59.87+1455+2005 -> 5906.87 | T17: 20 | U17: =SUM('Daily Halba'!$E17,'Daily Halba'!$H17,$M17:$T17) -> 7475.4801 | W17: 138.06 | Y17: 324 | AA17: 29 | AE17: =SUM(AA17:AD17) -> 29 | AN17: =SUM(AF17:AM17) -> 0 | AP17: =SUM(W17:Z17,AE17,AN17,AO17) -> 491.06 | AS17: ='Daily Halba'!$U17-'Daily Halba'!$AP17 -> 6984.4201
A18: 45973 | C18: ='ODOMETERS Halba'!J14 -> 1259 | D18: 0.7932 | E18: ='Daily Halba'!$C18*'Daily Halba'!$D18 -> 998.6388 | F18: ='ODOMETERS Halba'!K14 -> 962 | G18: 0.7932 | H18: ='Daily Halba'!$F18*'Daily Halba'!$G18 -> 763.0584 | I18: ='Daily Halba'!$C18+'Daily Halba'!$F18 -> 2221 | J18: ='Daily Halba'!$I18*'Daily Halba'!$G18 -> 1761.6972 | K18: ='ODOMETERS Halba'!L14 -> 1116 | L18: 0.7765 | M18: ='Daily Halba'!$K18*'Daily Halba'!$L18 -> 866.574 | N18: 37.36 | O18: 23.5 | P18: 36.87 | R18: 81 | S18: 100 | T18: 31.77 | U18: =SUM('Daily Halba'!$E18,'Daily Halba'!$H18,$M18:$T18) -> 2938.7712 | W18: =832.84+20 -> 852.84 | Y18: =31.06+321.89 -> 352.95 | AE18: =SUM(AA18:AD18) -> 0 | AN18: =SUM(AF18:AM18) -> 0 | AP18: =SUM(W18:Z18,AE18,AN18,AO18) -> 1205.79 | AS18: ='Daily Halba'!$U18-'Daily Halba'!$AP18 -> 1732.9812
A19: 45974 | C19: ='ODOMETERS Halba'!J15 -> 1577 | D19: 0.7932 | E19: ='Daily Halba'!$C19*'Daily Halba'!$D19 -> 1250.8764 | F19: ='ODOMETERS Halba'!K15 -> 1044 | G19: 0.7932 | H19: ='Daily Halba'!$F19*'Daily Halba'!$G19 -> 828.1008 | I19: ='Daily Halba'!$C19+'Daily Halba'!$F19 -> 2621 | J19: ='Daily Halba'!$I19*'Daily Halba'!$G19 -> 2078.9772 | K19: ='ODOMETERS Halba'!L15 -> 325 | L19: 0.7765 | M19: ='Daily Halba'!$K19*'Daily Halba'!$L19 -> 252.3625 | O19: 7.8 | R19: 36 | S19: 728 | T19: 35.89 | U19: =SUM('Daily Halba'!$E19,'Daily Halba'!$H19,$M19:$T19) -> 3139.0297 | W19: =30+33.44 -> 63.44 | Y19: =54.35+354 -> 408.35 | AC19: 81.41 | AE19: =SUM(AA19:AD19) -> 81.41 | AI19: 5 | AN19: =SUM(AF19:AM19) -> 5 | AP19: =SUM(W19:Z19,AE19,AN19,AO19) -> 558.2 | AS19: ='Daily Halba'!$U19-'Daily Halba'!$AP19 -> 2580.8297
A20: 45975 | B20: Pre Price | C20: ='ODOMETERS Halba'!J16 -> 517 | D20: 0.7932 | E20: ='Daily Halba'!$C20*'Daily Halba'!$D20 -> 410.0844 | F20: ='ODOMETERS Halba'!K16 -> 471 | G20: 0.7932 | H20: ='Daily Halba'!$F20*'Daily Halba'!$G20 -> 373.5972 | I20: ='Daily Halba'!$C20+'Daily Halba'!$F20 -> 988 | J20: ='Daily Halba'!$I20*'Daily Halba'!$G20 -> 783.6816 | K20: ='ODOMETERS Halba'!L16 -> 287 | L20: 0.7765 | M20: ='Daily Halba'!$K20*'Daily Halba'!$L20 -> 222.8555 | N20: 8.36 | T20: 15.6 | U20: =SUM('Daily Halba'!$E20,'Daily Halba'!$H20,$M20:$T20) -> 1030.4971 | W20: =161.05+22.29 -> 183.34 | Y20: 126.91 | AE20: =SUM(AA20:AD20) -> 0 | AN20: =SUM(AF20:AM20) -> 0 | AP20: =SUM(W20:Z20,AE20,AN20,AO20) -> 310.25 | AS20: ='Daily Halba'!$U20-'Daily Halba'!$AP20 -> 720.2471
A21: 45975 | B21: Post Price | C21: ='ODOMETERS Halba'!J17 -> 651 | D21: 0.8043 | E21: ='Daily Halba'!$C21*'Daily Halba'!$D21 -> 523.5993 | F21: ='ODOMETERS Halba'!K17 -> 434 | G21: 0.8043 | H21: ='Daily Halba'!$F21*'Daily Halba'!$G21 -> 349.0662 | I21: ='Daily Halba'!$C21+'Daily Halba'!$F21 -> 1085 | J21: ='Daily Halba'!$I21*'Daily Halba'!$G21 -> 872.6655 | K21: ='ODOMETERS Halba'!L17 -> 652 | L21: 0.796 | M21: ='Daily Halba'!$K21*'Daily Halba'!$L21 -> 518.992 | N21: 17.14 | O21: 7.8 | P21: 24.52 | R21: 46.75 | S21: 10 | T21: 46.72 | U21: =SUM('Daily Halba'!$E21,'Daily Halba'!$H21,$M21:$T21) -> 1544.5875 | W21: =489+11.13 -> 500.13 | Y21: 187.8 | AB21: 86 | AE21: =SUM(AA21:AD21) -> 86 | AN21: =SUM(AF21:AM21) -> 0 | AP21: =SUM(W21:Z21,AE21,AN21,AO21) -> 773.93 | AS21: ='Daily Halba'!$U21-'Daily Halba'!$AP21 -> 770.6575
A22: 45976 | C22: ='ODOMETERS Halba'!J18 -> 1696 | D22: 0.8043 | E22: ='Daily Halba'!$C22*'Daily Halba'!$D22 -> 1364.0928 | F22: ='ODOMETERS Halba'!K18 -> 820 | G22: 0.8043 | H22: ='Daily Halba'!$F22*'Daily Halba'!$G22 -> 659.526 | I22: ='Daily Halba'!$C22+'Daily Halba'!$F22 -> 2516 | J22: ='Daily Halba'!$I22*'Daily Halba'!$G22 -> 2023.6188 | K22: ='ODOMETERS Halba'!L18 -> 734 | L22: 0.796 | M22: ='Daily Halba'!$K22*'Daily Halba'!$L22 -> 584.264 | N22: 5.57 | O22: 6.68 | P22: 24.5 | R22: 61 | S22: 52.2 | T22: 60.7 | U22: =SUM('Daily Halba'!$E22,'Daily Halba'!$H22,$M22:$T22) -> 2818.5328 | W22: =54.6+45+10.6+296.83 -> 407.03 | Y22: 660.1 | AE22: =SUM(AA22:AD22) -> 0 | AN22: =SUM(AF22:AM22) -> 0 | AP22: =SUM(W22:Z22,AE22,AN22,AO22) -> 1067.13 | AS22: ='Daily Halba'!$U22-'Daily Halba'!$AP22 -> 1751.4028
A23: 45977 | C23: ='ODOMETERS Halba'!J19 -> 1921 | D23: 0.8043 | E23: ='Daily Halba'!$C23*'Daily Halba'!$D23 -> 1545.0603 | F23: ='ODOMETERS Halba'!K19 -> 968 | G23: 0.8043 | H23: ='Daily Halba'!$F23*'Daily Halba'!$G23 -> 778.5624 | I23: ='Daily Halba'!$C23+'Daily Halba'!$F23 -> 2889 | J23: ='Daily Halba'!$I23*'Daily Halba'!$G23 -> 2323.6227 | K23: ='ODOMETERS Halba'!L19 -> 387 | L23: 0.796 | M23: ='Daily Halba'!$K23*'Daily Halba'!$L23 -> 308.052 | N23: 38.36 | O23: 25.64 | P23: 24.52 | R23: 74 | T23: 18.39 | U23: =SUM('Daily Halba'!$E23,'Daily Halba'!$H23,$M23:$T23) -> 2812.5847 | W23: =5.57+6.68+48.8+31.92+203.68 -> 296.65 | Y23: 198.66 | Z23: -34 | AE23: =SUM(AA23:AD23) -> 0 | AG23: 150 | AN23: =SUM(AF23:AM23) -> 150 | AP23: =SUM(W23:Z23,AE23,AN23,AO23) -> 611.31 | AS23: ='Daily Halba'!$U23-'Daily Halba'!$AP23 -> 2201.2747
A24: 45978 | C24: ='ODOMETERS Halba'!J20 -> 1821 | D24: 0.8043 | E24: ='Daily Halba'!$C24*'Daily Halba'!$D24 -> 1464.6303 | F24: ='ODOMETERS Halba'!K20 -> 882 | G24: 0.8043 | H24: ='Daily Halba'!$F24*'Daily Halba'!$G24 -> 709.3926 | I24: ='Daily Halba'!$C24+'Daily Halba'!$F24 -> 2703 | J24: ='Daily Halba'!$I24*'Daily Halba'!$G24 -> 2174.0229 | K24: ='ODOMETERS Halba'!L20 -> 3761 | L24: 0.796 | M24: ='Daily Halba'!$K24*'Daily Halba'!$L24 -> 2993.756 | N24: 25.78 | O24: 13.91 | P24: 12.26 | R24: 77 | S24: =28+112 -> 140 | T24: 52.61 | U24: =SUM('Daily Halba'!$E24,'Daily Halba'!$H24,$M24:$T24) -> 5489.3389 | W24: =155.64+2678 -> 2833.64 | Y24: 262 | AB24: 190 | AE24: =SUM(AA24:AD24) -> 190 | AN24: =SUM(AF24:AM24) -> 0 | AP24: =SUM(W24:Z24,AE24,AN24,AO24) -> 3285.64 | AS24: ='Daily Halba'!$U24-'Daily Halba'!$AP24 -> 2203.6989
A25: 45979 | B25: Pre Price | C25: ='ODOMETERS Halba'!J21 -> 800 | D25: 0.8043 | E25: ='Daily Halba'!$C25*'Daily Halba'!$D25 -> 643.44 | F25: ='ODOMETERS Halba'!K21 -> 445 | G25: 0.8043 | H25: ='Daily Halba'!$F25*'Daily Halba'!$G25 -> 357.9135 | I25: ='Daily Halba'!$C25+'Daily Halba'!$F25 -> 1245 | J25: ='Daily Halba'!$I25*'Daily Halba'!$G25 -> 1001.3535 | K25: ='ODOMETERS Halba'!L21 -> 71 | L25: 0.796 | M25: ='Daily Halba'!$K25*'Daily Halba'!$L25 -> 56.516 | N25: 6 | S25: 770 | T25: 15.82 | U25: =SUM('Daily Halba'!$E25,'Daily Halba'!$H25,$M25:$T25) -> 1849.6895 | Y25: 230.43 | Z25: 6 | AE25: =SUM(AA25:AD25) -> 0 | AN25: =SUM(AF25:AM25) -> 0 | AP25: =SUM(W25:Z25,AE25,AN25,AO25) -> 236.43 | AS25: ='Daily Halba'!$U25-'Daily Halba'!$AP25 -> 1613.2595
A26: 45979 | B26: Post Price | C26: ='ODOMETERS Halba'!J22 -> 773 | D26: 0.8082 | E26: ='Daily Halba'!$C26*'Daily Halba'!$D26 -> 624.7386 | F26: ='ODOMETERS Halba'!K22 -> 406 | G26: 0.8082 | H26: ='Daily Halba'!$F26*'Daily Halba'!$G26 -> 328.1292 | I26: ='Daily Halba'!$C26+'Daily Halba'!$F26 -> 1179 | J26: ='Daily Halba'!$I26*'Daily Halba'!$G26 -> 952.8678 | K26: ='ODOMETERS Halba'!L22 -> 643 | L26: 0.801 | M26: ='Daily Halba'!$K26*'Daily Halba'!$L26 -> 515.043 | N26: 6 | O26: 13.37 | R26: 36 | S26: 150 | T26: =8.5+23.69 -> 32.19 | U26: =SUM('Daily Halba'!$E26,'Daily Halba'!$H26,$M26:$T26) -> 1705.4708 | W26: =80+214+190 -> 484 | Z26: 47 | AA26: =64+80 -> 144 | AB26: =63.54 -> 63.54 | AC26: 70 | AE26: =SUM(AA26:AD26) -> 277.54 | AJ26: 80 | AN26: =SUM(AF26:AM26) -> 80 | AP26: =SUM(W26:Z26,AE26,AN26,AO26) -> 888.54 | AQ26: Klinex | AS26: ='Daily Halba'!$U26-'Daily Halba'!$AP26 -> 816.9308
A27: 45980 | C27: ='ODOMETERS Halba'!J23 -> 1436 | D27: 0.8082 | E27: ='Daily Halba'!$C27*'Daily Halba'!$D27 -> 1160.5752 | F27: ='ODOMETERS Halba'!K23 -> 1345 | G27: 0.8082 | H27: ='Daily Halba'!$F27*'Daily Halba'!$G27 -> 1087.029 | I27: ='Daily Halba'!$C27+'Daily Halba'!$F27 -> 2781 | J27: ='Daily Halba'!$I27*'Daily Halba'!$G27 -> 2247.6042 | K27: ='ODOMETERS Halba'!L23 -> 662 | L27: 0.801 | M27: ='Daily Halba'!$K27*'Daily Halba'!$L27 -> 530.262 | N27: 8.3 | O27: =15.6+2.2 -> 17.8 | P27: 36.7 | R27: 31 | S27: 158 | T27: 56 | U27: =SUM('Daily Halba'!$E27,'Daily Halba'!$H27,$M27:$T27) -> 3085.6662 | W27: =207-125-7 -> 75 | Y27: =350.75+344.4 -> 695.15 | AE27: =SUM(AA27:AD27) -> 0 | AH27: 125 | AI27: =7 -> 7 | AN27: =SUM(AF27:AM27) -> 132 | AP27: =SUM(W27:Z27,AE27,AN27,AO27) -> 902.15 | AQ27: Kiosk Paint | AS27: ='Daily Halba'!$U27-'Daily Halba'!$AP27 -> 2183.5162
A28: 45981 | C28: ='ODOMETERS Halba'!J24 -> 1442 | D28: 0.8082 | E28: ='Daily Halba'!$C28*'Daily Halba'!$D28 -> 1165.4244 | F28: ='ODOMETERS Halba'!K24 -> 898 | G28: 0.8082 | H28: ='Daily Halba'!$F28*'Daily Halba'!$G28 -> 725.7636 | I28: ='Daily Halba'!$C28+'Daily Halba'!$F28 -> 2340 | J28: ='Daily Halba'!$I28*'Daily Halba'!$G28 -> 1891.188 | K28: ='ODOMETERS Halba'!L24 -> 936 | L28: 0.801 | M28: ='Daily Halba'!$K28*'Daily Halba'!$L28 -> 749.736 | N28: 5.57 | O28: 21.18 | P28: 12.26 | Q28: 25 | R28: 57 | S28: 4300 | T28: 39.52 | U28: =SUM('Daily Halba'!$E28,'Daily Halba'!$H28,$M28:$T28) -> 7101.454 | W28: =20.6+395 -> 415.6 | Y28: =149+323.39+247 -> 719.39 | Z28: 47 | AA28: 133 | AB28: 220 | AC28: 81.96 | AE28: =SUM(AA28:AD28) -> 434.96 | AN28: =SUM(AF28:AM28) -> 0 | AP28: =SUM(W28:Z28,AE28,AN28,AO28) -> 1616.95 | AS28: ='Daily Halba'!$U28-'Daily Halba'!$AP28 -> 5484.504
A29: 45982 | B29: Pre Price | C29: ='ODOMETERS Halba'!J25 -> 632 | D29: 0.8082 | E29: ='Daily Halba'!$C29*'Daily Halba'!$D29 -> 510.7824 | F29: ='ODOMETERS Halba'!K25 -> 497 | G29: 0.8082 | H29: ='Daily Halba'!$F29*'Daily Halba'!$G29 -> 401.6754 | I29: ='Daily Halba'!$C29+'Daily Halba'!$F29 -> 1129 | J29: ='Daily Halba'!$I29*'Daily Halba'!$G29 -> 912.4578 | K29: ='ODOMETERS Halba'!L25 -> 188 | L29: 0.801 | M29: ='Daily Halba'!$K29*'Daily Halba'!$L29 -> 150.588 | T29: 5.79 | U29: =SUM('Daily Halba'!$E29,'Daily Halba'!$H29,$M29:$T29) -> 1068.8358 | W29: 41.18 | Y29: =68.69+1812 -> 1880.69 | AE29: =SUM(AA29:AD29) -> 0 | AH29: 290 | AN29: =SUM(AF29:AM29) -> 290 | AP29: =SUM(W29:Z29,AE29,AN29,AO29) -> 2211.87 | AQ29: Mezout tank hatch repair and hoover purchase | AS29: ='Daily Halba'!$U29-'Daily Halba'!$AP29 -> -1143.0342
A30: 45982 | B30: Post Price | C30: ='ODOMETERS Halba'!J26 -> 827 | D30: 0.8127 | E30: ='Daily Halba'!$C30*'Daily Halba'!$D30 -> 672.1029 | F30: ='ODOMETERS Halba'!K26 -> 835 | G30: 0.8127 | H30: ='Daily Halba'!$F30*'Daily Halba'!$G30 -> 678.6045 | I30: ='Daily Halba'!$C30+'Daily Halba'!$F30 -> 1662 | J30: ='Daily Halba'!$I30*'Daily Halba'!$G30 -> 1350.7074 | K30: ='ODOMETERS Halba'!L26 -> 1076 | L30: 0.811 | M30: ='Daily Halba'!$K30*'Daily Halba'!$L30 -> 872.636 | N30: 6 | O30: 17.91 | Q30: 5 | R30: 37 | T30: 8.58 | U30: =SUM('Daily Halba'!$E30,'Daily Halba'!$H30,$M30:$T30) -> 2297.8334 | W30: =766+554 -> 1320 | Y30: 83.7 | AA30: 104 | AE30: =SUM(AA30:AD30) -> 104 | AN30: =SUM(AF30:AM30) -> 0 | AP30: =SUM(W30:Z30,AE30,AN30,AO30) -> 1507.7 | AS30: ='Daily Halba'!$U30-'Daily Halba'!$AP30 -> 790.1334
A31: 45983 | C31: ='ODOMETERS Halba'!J27 -> 1892 | D31: 0.8127 | E31: ='Daily Halba'!$C31*'Daily Halba'!$D31 -> 1537.6284 | F31: ='ODOMETERS Halba'!K27 -> 1240 | G31: 0.8127 | H31: ='Daily Halba'!$F31*'Daily Halba'!$G31 -> 1007.748 | I31: ='Daily Halba'!$C31+'Daily Halba'!$F31 -> 3132 | J31: ='Daily Halba'!$I31*'Daily Halba'!$G31 -> 2545.3764 | K31: ='ODOMETERS Halba'!L27 -> 1531 | L31: 0.811 | M31: ='Daily Halba'!$K31*'Daily Halba'!$L31 -> 1241.641 | N31: 13.54 | O31: 20 | P31: 12.26 | R31: =17+87 -> 104 | S31: 611 | T31: 15.83 | U31: =SUM('Daily Halba'!$E31,'Daily Halba'!$H31,$M31:$T31) -> 4563.6474 | W31: =272.55+892 -> 1164.55 | Y31: 116 | AE31: =SUM(AA31:AD31) -> 0 | AN31: =SUM(AF31:AM31) -> 0 | AP31: =SUM(W31:Z31,AE31,AN31,AO31) -> 1280.55 | AS31: ='Daily Halba'!$U31-'Daily Halba'!$AP31 -> 3283.0974
A32: 45984 | C32: ='ODOMETERS Halba'!J28 -> 1682 | D32: 0.8127 | E32: ='Daily Halba'!$C32*'Daily Halba'!$D32 -> 1366.9614 | F32: ='ODOMETERS Halba'!K28 -> 771 | G32: 0.8127 | H32: ='Daily Halba'!$F32*'Daily Halba'!$G32 -> 626.5917 | I32: ='Daily Halba'!$C32+'Daily Halba'!$F32 -> 2453 | J32: ='Daily Halba'!$I32*'Daily Halba'!$G32 -> 1993.5531 | K32: ='ODOMETERS Halba'!L28 -> 246 | L32: 0.811 | M32: ='Daily Halba'!$K32*'Daily Halba'!$L32 -> 199.506 | N32: 15.57 | O32: 17.83 | R32: 64 | S32: 2.45 | U32: =SUM('Daily Halba'!$E32,'Daily Halba'!$H32,$M32:$T32) -> 2292.9091 | W32: 42.8 | Y32: 48 | AE32: =SUM(AA32:AD32) -> 0 | AN32: =SUM(AF32:AM32) -> 0 | AP32: =SUM(W32:Z32,AE32,AN32,AO32) -> 90.8 | AS32: ='Daily Halba'!$U32-'Daily Halba'!$AP32 -> 2202.1091
A33: 45985 | C33: ='ODOMETERS Halba'!J29 -> 1407 | D33: 0.8127 | E33: ='Daily Halba'!$C33*'Daily Halba'!$D33 -> 1143.4689 | F33: ='ODOMETERS Halba'!K29 -> 969 | G33: 0.8127 | H33: ='Daily Halba'!$F33*'Daily Halba'!$G33 -> 787.5063 | I33: ='Daily Halba'!$C33+'Daily Halba'!$F33 -> 2376 | J33: ='Daily Halba'!$I33*'Daily Halba'!$G33 -> 1930.9752 | K33: ='ODOMETERS Halba'!L29 -> 1205 | L33: 0.811 | M33: ='Daily Halba'!$K33*'Daily Halba'!$L33 -> 977.255 | N33: 8.36 | O33: 7.8 | R33: 216 | S33: =947+7741 -> 8688 | T33: 13.37 | U33: =SUM('Daily Halba'!$E33,'Daily Halba'!$H33,$M33:$T33) -> 11841.76 | W33: =33.44+159+616+50 -> 858.44 | Y33: =63.39+361 -> 424.39 | AB33: =59.75+40+118 -> 217.75 | AE33: =SUM(AA33:AD33) -> 217.75 | AN33: =SUM(AF33:AM33) -> 0 | AP33: =SUM(W33:Z33,AE33,AN33,AO33) -> 1500.58 | AS33: ='Daily Halba'!$U33-'Daily Halba'!$AP33 -> 10341.18
A34: 45986 | B34: Pre Price | C34: ='ODOMETERS Halba'!J30 -> 861 | D34: 0.8127 | E34: ='Daily Halba'!$C34*'Daily Halba'!$D34 -> 699.7347 | F34: ='ODOMETERS Halba'!K30 -> 329 | G34: 0.8127 | H34: ='Daily Halba'!$F34*'Daily Halba'!$G34 -> 267.3783 | I34: ='Daily Halba'!$C34+'Daily Halba'!$F34 -> 1190 | J34: ='Daily Halba'!$I34*'Daily Halba'!$G34 -> 967.113 | K34: ='ODOMETERS Halba'!L30 -> 117 | L34: 0.811 | M34: ='Daily Halba'!$K34*'Daily Halba'!$L34 -> 94.887 | P34: 12.26 | T34: 7.8 | U34: =SUM('Daily Halba'!$E34,'Daily Halba'!$H34,$M34:$T34) -> 1082.06 | W34: 10 | Y34: =65+36.5 -> 101.5 | AE34: =SUM(AA34:AD34) -> 0 | AN34: =SUM(AF34:AM34) -> 0 | AP34: =SUM(W34:Z34,AE34,AN34,AO34) -> 111.5 | AS34: ='Daily Halba'!$U34-'Daily Halba'!$AP34 -> 970.56
A35: 45986 | B35: Post Price | C35: ='ODOMETERS Halba'!J31 -> 774 | D35: 0.8138 | E35: ='Daily Halba'!$C35*'Daily Halba'!$D35 -> 629.8812 | F35: ='ODOMETERS Halba'!K31 -> 583 | G35: 0.8138 | H35: ='Daily Halba'!$F35*'Daily Halba'!$G35 -> 474.4454 | I35: ='Daily Halba'!$C35+'Daily Halba'!$F35 -> 1357 | J35: ='Daily Halba'!$I35*'Daily Halba'!$G35 -> 1104.3266 | K35: ='ODOMETERS Halba'!L31 -> 349 | L35: 0.8138 | M35: ='Daily Halba'!$K35*'Daily Halba'!$L35 -> 284.0162 | N35: 19.57 | O35: 3 | P35: 36.78 | R35: 43 | T35: 9.19 | U35: =SUM('Daily Halba'!$E35,'Daily Halba'!$H35,$M35:$T35) -> 1499.8828 | W35: =118.71+5+80 -> 203.71 | Y35: =70.8+81.38+170 -> 322.18 | AE35: =SUM(AA35:AD35) -> 0 | AN35: =SUM(AF35:AM35) -> 0 | AP35: =SUM(W35:Z35,AE35,AN35,AO35) -> 525.89 | AS35: ='Daily Halba'!$U35-'Daily Halba'!$AP35 -> 973.9928
A36: 45987 | C36: ='ODOMETERS Halba'!J32 -> 1141 | D36: 0.8138 | E36: ='Daily Halba'!$C36*'Daily Halba'!$D36 -> 928.5458 | F36: ='ODOMETERS Halba'!K32 -> 856 | G36: 0.8138 | H36: ='Daily Halba'!$F36*'Daily Halba'!$G36 -> 696.6128 | I36: ='Daily Halba'!$C36+'Daily Halba'!$F36 -> 1997 | J36: ='Daily Halba'!$I36*'Daily Halba'!$G36 -> 1625.1586 | K36: ='ODOMETERS Halba'!L32 -> 472 | L36: 0.8138 | M36: ='Daily Halba'!$K36*'Daily Halba'!$L36 -> 384.1136 | O36: 3 | P36: 49.13 | R36: 36 | U36: =SUM('Daily Halba'!$E36,'Daily Halba'!$H36,$M36:$T36) -> 2097.4022 | W36: =10.57+63.57+164.38 -> 238.52 | AB36: =254+17.83 -> 271.83 | AE36: =SUM(AA36:AD36) -> 271.83 | AI36: 10.57 | AK36: 16.72 | AN36: =SUM(AF36:AM36) -> 27.29 | AP36: =SUM(W36:Z36,AE36,AN36,AO36) -> 537.64 | AS36: ='Daily Halba'!$U36-'Daily Halba'!$AP36 -> 1559.7622
A37: 45988 | C37: ='ODOMETERS Halba'!J33 -> 1699 | D37: 0.8138 | E37: ='Daily Halba'!$C37*'Daily Halba'!$D37 -> 1382.6462 | F37: ='ODOMETERS Halba'!K33 -> 1015 | G37: 0.8138 | H37: ='Daily Halba'!$F37*'Daily Halba'!$G37 -> 826.007 | I37: ='Daily Halba'!$C37+'Daily Halba'!$F37 -> 2714 | J37: ='Daily Halba'!$I37*'Daily Halba'!$G37 -> 2208.6532 | K37: ='ODOMETERS Halba'!L33 -> 406 | L37: 0.8138 | M37: ='Daily Halba'!$K37*'Daily Halba'!$L37 -> 330.4028 | N37: 33.93 | O37: 17.83 | P37: 24.52 | Q37: 10 | R37: 54 | S37: 100 | T37: 26.68 | U37: =SUM('Daily Halba'!$E37,'Daily Halba'!$H37,$M37:$T37) -> 2806.016 | W37: 43.18 | Y37: =203.45+65.1 -> 268.55 | AB37: 209 | AC37: 165.5 | AE37: =SUM(AA37:AD37) -> 374.5 | AI37: 6.51 | AN37: =SUM(AF37:AM37) -> 6.51 | AP37: =SUM(W37:Z37,AE37,AN37,AO37) -> 692.74 | AS37: ='Daily Halba'!$U37-'Daily Halba'!$AP37 -> 2113.276
A38: 45989 | C38: ='ODOMETERS Halba'!J34 -> 1674 | D38: 0.8138 | E38: ='Daily Halba'!$C38*'Daily Halba'!$D38 -> 1362.3012 | F38: ='ODOMETERS Halba'!K34 -> 1419 | G38: 0.8138 | H38: ='Daily Halba'!$F38*'Daily Halba'!$G38 -> 1154.7822 | I38: ='Daily Halba'!$C38+'Daily Halba'!$F38 -> 3093 | J38: ='Daily Halba'!$I38*'Daily Halba'!$G38 -> 2517.0834 | K38: ='ODOMETERS Halba'!L34 -> 721 | L38: 0.8138 | M38: ='Daily Halba'!$K38*'Daily Halba'!$L38 -> 586.7498 | N38: 25.57 | O38: 8.7 | P38: 12.26 | R38: 125 | S38: =80+570*0.8138 -> 543.866 | T38: 18.29 | U38: =SUM('Daily Halba'!$E38,'Daily Halba'!$H38,$M38:$T38) -> 3837.5192 | X38: =570*0.8138 -> 463.866 | Y38: 69.98 | AA38: =217.57+309 -> 526.57 | AB38: 26.3 | AE38: =SUM(AA38:AD38) -> 552.87 | AN38: =SUM(AF38:AM38) -> 0 | AP38: =SUM(W38:Z38,AE38,AN38,AO38) -> 1086.716 | AS38: ='Daily Halba'!$U38-'Daily Halba'!$AP38 -> 2750.8032
A39: 45990 | C39: ='ODOMETERS Halba'!J35 -> 1688 | D39: 0.8138 | E39: ='Daily Halba'!$C39*'Daily Halba'!$D39 -> 1373.6944 | F39: ='ODOMETERS Halba'!K35 -> 1199 | G39: 0.8138 | H39: ='Daily Halba'!$F39*'Daily Halba'!$G39 -> 975.7462 | I39: ='Daily Halba'!$C39+'Daily Halba'!$F39 -> 2887 | J39: ='Daily Halba'!$I39*'Daily Halba'!$G39 -> 2349.4406 | K39: ='ODOMETERS Halba'!L35 -> 592 | L39: 0.8071 | M39: ='Daily Halba'!$K39*'Daily Halba'!$L39 -> 477.8032 | N39: 24.36 | O39: 12.26 | P39: 12.26 | R39: 57 | T39: 3.34 | U39: =SUM('Daily Halba'!$E39,'Daily Halba'!$H39,$M39:$T39) -> 2936.4638 | W39: 242 | Y39: 32.55 | AA39: 250 | AE39: =SUM(AA39:AD39) -> 250 | AI39: 7 | AJ39: 238 | AN39: =SUM(AF39:AM39) -> 245 | AP39: =SUM(W39:Z39,AE39,AN39,AO39) -> 769.55 | AS39: ='Daily Halba'!$U39-'Daily Halba'!$AP39 -> 2166.9138
A40: 45991 | C40: ='ODOMETERS Halba'!J36 -> 1440 | D40: 0.8138 | E40: ='Daily Halba'!$C40*'Daily Halba'!$D40 -> 1171.872 | F40: ='ODOMETERS Halba'!K36 -> 921 | G40: 0.8138 | H40: ='Daily Halba'!$F40*'Daily Halba'!$G40 -> 749.5098 | I40: ='Daily Halba'!$C40+'Daily Halba'!$F40 -> 2361 | J40: ='Daily Halba'!$I40*'Daily Halba'!$G40 -> 1921.3818 | K40: ='ODOMETERS Halba'!L36 -> 762 | L40: 0.8071 | M40: ='Daily Halba'!$K40*'Daily Halba'!$L40 -> 615.0102 | N40: 20 | O40: 17.8 | P40: 36.87 | R40: 58 | T40: 1.67 | U40: =SUM('Daily Halba'!$E40,'Daily Halba'!$H40,$M40:$T40) -> 2670.732 | W40: =30+30+20+242 -> 322 | Y40: 45.5 | AE40: =SUM(AA40:AD40) -> 0 | AI40: 6 | AN40: =SUM(AF40:AM40) -> 6 | AP40: =SUM(W40:Z40,AE40,AN40,AO40) -> 373.5 | AS40: ='Daily Halba'!$U40-'Daily Halba'!$AP40 -> 2297.232
A41: 45992 | C41: ='ODOMETERS Halba'!J37 -> 1557 | D41: 0.8138 | E41: ='Daily Halba'!$C41*'Daily Halba'!$D41 -> 1267.0866 | F41: ='ODOMETERS Halba'!K37 -> 929 | G41: 0.8138 | H41: ='Daily Halba'!$F41*'Daily Halba'!$G41 -> 756.0202 | I41: ='Daily Halba'!$C41+'Daily Halba'!$F41 -> 2486 | J41: ='Daily Halba'!$I41*'Daily Halba'!$G41 -> 2023.1068 | K41: ='ODOMETERS Halba'!L37 -> 5937 | L41: 0.8071 | M41: ='Daily Halba'!$K41*'Daily Halba'!$L41 -> 4791.7527 | N41: 10.87 | O41: 12.26 | P41: 49.05 | R41: 47 | S41: 930 | T41: 1.5 | U41: =SUM('Daily Halba'!$E41,'Daily Halba'!$H41,$M41:$T41) -> 7865.5395 | W41: =14.49+2825+15+50+20+717.5+957 -> 4598.99 | Y41: 16.27 | Z41: 9 | AB41: 10.5 | AE41: =SUM(AA41:AD41) -> 10.5 | AN41: =SUM(AF41:AM41) -> 0 | AP41: =SUM(W41:Z41,AE41,AN41,AO41) -> 4634.76 | AS41: ='Daily Halba'!$U41-'Daily Halba'!$AP41 -> 3230.7795
...

Sheet BM Stock Halba
A1: OUT | H1: IN
A2: Type | B2: Initial | C2: Out | D2: In | E2: Current | H2: Date | I2: Benzine 1 | J2: Benzine 2 | K2: Benzine Backup | L2: Mezout | M2: Price | N2: Total
A3: Benzine 1 | B3: =8567-189+224+551+2463-41+88 -> 11663 | C3: ='ODOMETERS Halba'!J1 -> 494093 | D3: =I184 -> 494820 | E3: =B3-C3+D3 -> 12390 | H3: 45967 | L3: 2987 | M3: =14.25/20 -> 0.7125 | N3: =SUM('BM Stock Halba'!$I3:$L3)*'BM Stock Halba'!$M3 -> 2128.2375
A4: Benzine 2 | B4: =6041-96-1947-142+16 -> 3872 | C4: ='ODOMETERS Halba'!K1 -> 396810 | D4: =J184 -> 401968 | E4: =B4-C4+D4 -> 9030 | H4: 45967 | I4: 4849 | M4: =14.4/20 -> 0.72 | N4: =SUM('BM Stock Halba'!$I4:$L4)*'BM Stock Halba'!$M4 -> 3491.28
A5: Total Benzine | B5: =B3+B4 -> 15535 | C5: =C3+C4 -> 890903 | D5: =D3+D4 -> 896788 | E5: =E3+E4 -> 21420 | H5: 45971 | I5: 3025 | J5: =2950+3095 -> 6045 | M5: =14.55/20 -> 0.7275 | N5: =SUM('BM Stock Halba'!$I5:$L5)*'BM Stock Halba'!$M5 -> 6598.425
A6: Mezout | B6: =16143-24-636+256 -> 15739 | C6: ='ODOMETERS Halba'!L1 -> 315152 | D6: =L184 -> 303103 | E6: =B6-C6+D6 -> 3690 | H6: 45972 | L6: 4078 | M6: =14.55/20 -> 0.7275 | N6: =SUM('BM Stock Halba'!$I6:$L6)*'BM Stock Halba'!$M6 -> 2966.745
A7: GRAND TOTAL | B7: =SUM(B5:B6) -> 31274 | C7: =SUM(C5:C6) -> 1206055 | D7: =SUM(D5:D6) -> 1199891 | E7: =SUM(E5:E6) -> 25110 | H7: 45972 | I7: 4625 | M7: =14.55/20 -> 0.7275 | N7: =SUM('BM Stock Halba'!$I7:$L7)*'BM Stock Halba'!$M7 -> 3364.6875
H8: 45974 | L8: 8748 | M8: 0.74 | N8: =SUM('BM Stock Halba'!$I8:$L8)*'BM Stock Halba'!$M8 -> 6473.52
H9: 45974 | I9: 7010 | J9: 9897 | M9: 0.7275 | N9: =SUM('BM Stock Halba'!$I9:$L9)*'BM Stock Halba'!$M9 -> 12299.843
H10: 45981 | L10: 8098 | M10: 0.7125 | N10: =SUM('BM Stock Halba'!$I10:$L10)*'BM Stock Halba'!$M10 -> 5769.825
H11: 45981 | I11: 8859 | J11: 3085 | M11: 0.746 | N11: =SUM('BM Stock Halba'!$I11:$L11)*'BM Stock Halba'!$M11 -> 8910.224
H12: 45987 | I12: 9903 | J12: 6059 | M12: 0.7495 | N12: =SUM('BM Stock Halba'!$I12:$L12)*'BM Stock Halba'!$M12 -> 11963.519
H13: 45994 | I13: 4166 | J13: 4088 | M13: 0.75 | N13: =SUM('BM Stock Halba'!$I13:$L13)*'BM Stock Halba'!$M13 -> 6190.5
H14: 45996 | I14: 4096 | J14: 3071 | M14: 0.75 | N14: =SUM('BM Stock Halba'!$I14:$L14)*'BM Stock Halba'!$M14 -> 5375.25
H15: 45996 | L15: 2962 | M15: 0.7495 | N15: =SUM('BM Stock Halba'!$I15:$L15)*'BM Stock Halba'!$M15 -> 2220.019
H16: 45998 | L16: 3085 | M16: 0.743 | N16: =SUM('BM Stock Halba'!$I16:$L16)*'BM Stock Halba'!$M16 -> 2292.155
H17: 46000 | I17: =3068+4092 -> 7160 | J17: =2998+2944 -> 5942 | M17: =14.95/20 -> 0.7475 | N17: =SUM('BM Stock Halba'!$I17:$L17)*'BM Stock Halba'!$M17 -> 9793.745
H18: 46003 | L18: 6082 | M18: =14.3/20 -> 0.715 | N18: =SUM('BM Stock Halba'!$I18:$L18)*'BM Stock Halba'!$M18 -> 4348.63
H19: 46003 | I19: 4099 | J19: 2948 | M19: =14.86/20 -> 0.743 | N19: =SUM('BM Stock Halba'!$I19:$L19)*'BM Stock Halba'!$M19 -> 5235.921
H20: 46007 | I20: 5960 | J20: 3070 | M20: =14.66/20 -> 0.733 | N20: =SUM('BM Stock Halba'!$I20:$L20)*'BM Stock Halba'!$M20 -> 6618.99
H21: 46007 | L21: 4021 | M21: =13.98/20 -> 0.699 | N21: =SUM('BM Stock Halba'!$I21:$L21)*'BM Stock Halba'!$M21 -> 2810.679
H22: 46010 | I22: 4896 | J22: 4662 | M22: =14.37/20 -> 0.7185 | N22: =SUM('BM Stock Halba'!$I22:$L22)*'BM Stock Halba'!$M22 -> 6867.423
H23: 46010 | L23: 3079 | M23: =13.68/20 -> 0.684 | N23: =SUM('BM Stock Halba'!$I23:$L23)*'BM Stock Halba'!$M23 -> 2106.036
H24: 46013 | L24: 226 | M24: Return to tank
H25: 46013 | I25: 2985 | M25: =14.32/20 -> 0.716 | N25: =SUM('BM Stock Halba'!$I25:$L25)*'BM Stock Halba'!$M25 -> 2137.26
H26: 46013 | L26: 600 | M26: =13.64/20 -> 0.682 | N26: =SUM('BM Stock Halba'!$I26:$L26)*'BM Stock Halba'!$M26 -> 409.2
H27: 46014 | J27: 4116 | M27: =14.1/20 -> 0.705 | N27: =SUM('BM Stock Halba'!$I27:$L27)*'BM Stock Halba'!$M27 -> 2901.78
H28: 46014 | L28: 4186 | M28: =13.44/20 -> 0.672 | N28: =SUM('BM Stock Halba'!$I28:$L28)*'BM Stock Halba'!$M28 -> 2812.992
H29: 46015 | I29: 6090 | M29: =14.1/20 -> 0.705 | N29: =SUM('BM Stock Halba'!$I29:$L29)*'BM Stock Halba'!$M29 -> 4293.45
H30: 46017 | L30: 3012 | M30: =13.23/20 -> 0.6615 | N30: =SUM('BM Stock Halba'!$I30:$L30)*'BM Stock Halba'!$M30 -> 1992.438
H31: 46017 | I31: 4671 | J31: 4121 | M31: =13.8/20 -> 0.69 | N31: =SUM('BM Stock Halba'!$I31:$L31)*'BM Stock Halba'!$M31 -> 6066.48
H32: 46021 | I32: 4114 | J32: 3084 | M32: =13.7/20 -> 0.685 | N32: =SUM('BM Stock Halba'!$I32:$L32)*'BM Stock Halba'!$M32 -> 4930.63
H33: 46021 | L33: 4109 | M33: =13.11/20 -> 0.6555 | N33: =SUM('BM Stock Halba'!$I33:$L33)*'BM Stock Halba'!$M33 -> 2693.4495
H34: 46022 | I34: 4895 | M34: =13.62/20 -> 0.681 | N34: =SUM('BM Stock Halba'!$I34:$L34)*'BM Stock Halba'!$M34 -> 3333.495
H35: 46022 | L35: 4033 | M35: =13.11/20 -> 0.6555 | N35: =SUM('BM Stock Halba'!$I35:$L35)*'BM Stock Halba'!$M35 -> 2643.6315
H36: 46024 | I36: 2500 | J36: 4114 | M36: =13.35/20 -> 0.6675 | N36: =SUM('BM Stock Halba'!$I36:$L36)*'BM Stock Halba'!$M36 -> 4414.845
H37: 46024 | L37: 4111 | M37: =12.97/20 -> 0.6485 | N37: =SUM('BM Stock Halba'!$I37:$L37)*'BM Stock Halba'!$M37 -> 2665.9835
H38: 46027 | I38: 4027 | J38: 2969 | M38: =13.45/20 -> 0.6725 | N38: =SUM('BM Stock Halba'!$I38:$L38)*'BM Stock Halba'!$M38 -> 4704.81
H39: 46027 | L39: 3080 | M39: =13.07/20 -> 0.6535 | N39: =SUM('BM Stock Halba'!$I39:$L39)*'BM Stock Halba'!$M39 -> 2012.78
H40: 46029 | I40: 4184 | J40: 4119 | M40: =13.3/20 -> 0.665 | N40: =SUM('BM Stock Halba'!$I40:$L40)*'BM Stock Halba'!$M40 -> 5521.495
...

Sheet ODOMETERS Halba
A1: Initial Odo | C1: Sales In Liters | H1: 6416973 | J1: =SUM(Table_1[Benzine 1]) -> 494093 | K1: =SUM(Table_1[Benzine 2]) -> 396810 | L1: =SUM(Table_1[Mezout]) -> 315152
A2: Date | B2: At new Pricing | C2: Benzine 1 A | D2: Benzine 1 B | E2: Benzine 2 A | F2: Benzine B | G2: Mezout A | H2: Mezout B | I2: NOTHING HERE | J2: Benzine 1 | K2: Benzine 2 | L2: Mezout | M2: total
A3: Initial Odo | C3: 36249 | D3: 12951 | E3: 27540 | F3: 7191 | G3: 6614230 | H3: 6416973
A4: 45965 | C4: 37203 | D4: 13431 | E4: 28569 | F4: 7466 | G4: 6614729 | H4: 6417061 | J4: ='ODOMETERS Halba'!$C4+'ODOMETERS Halba'!$D4-D3-C3 -> 1434 | K4: ='ODOMETERS Halba'!$E4+'ODOMETERS Halba'!$F4-F3-E3 -> 1304 | L4: ='ODOMETERS Halba'!$G4+'ODOMETERS Halba'!$H4-H3-G3 -> 587 | M4: ='ODOMETERS Halba'!$J4+'ODOMETERS Halba'!$K4+'ODOMETERS Halba'!$L4 -> 3325
A5: 45966 | C5: 37855 | D5: 13814 | E5: 29326 | F5: 7605 | G5: 6615020 | H5: 6417187 | J5: ='ODOMETERS Halba'!$C5+'ODOMETERS Halba'!$D5-D4-C4 -> 1035 | K5: ='ODOMETERS Halba'!$E5+'ODOMETERS Halba'!$F5-F4-E4 -> 896 | L5: ='ODOMETERS Halba'!$G5+'ODOMETERS Halba'!$H5-H4-G4 -> 417 | M5: ='ODOMETERS Halba'!$J5+'ODOMETERS Halba'!$K5+'ODOMETERS Halba'!$L5 -> 2348
A6: 45967 | C6: 38625 | D6: 14258 | E6: 30174 | F6: 7731 | G6: 6615340 | H6: 6417308 | J6: ='ODOMETERS Halba'!$C6+'ODOMETERS Halba'!$D6-D5-C5 -> 1214 | K6: ='ODOMETERS Halba'!$E6+'ODOMETERS Halba'!$F6-F5-E5 -> 974 | L6: ='ODOMETERS Halba'!$G6+'ODOMETERS Halba'!$H6-H5-G5 -> 441 | M6: ='ODOMETERS Halba'!$J6+'ODOMETERS Halba'!$K6+'ODOMETERS Halba'!$L6 -> 2629
A7: 45968 | B7: Pre Price | C7: 39057 | D7: 14436 | E7: 30546 | F7: 7817 | G7: 6615535 | H7: 6417425 | J7: ='ODOMETERS Halba'!$C7+'ODOMETERS Halba'!$D7-D6-C6 -> 610 | K7: ='ODOMETERS Halba'!$E7+'ODOMETERS Halba'!$F7-F6-E6 -> 458 | L7: ='ODOMETERS Halba'!$G7+'ODOMETERS Halba'!$H7-H6-G6 -> 312 | M7: ='ODOMETERS Halba'!$J7+'ODOMETERS Halba'!$K7+'ODOMETERS Halba'!$L7 -> 1380
A8: 45968 | B8: Post Price | C8: 39403 | D8: 14617 | E8: 30987 | F8: 7957 | G8: 6615646 | H8: 6417483 | J8: ='ODOMETERS Halba'!$C8+'ODOMETERS Halba'!$D8-D7-C7 -> 527 | K8: ='ODOMETERS Halba'!$E8+'ODOMETERS Halba'!$F8-F7-E7 -> 581 | L8: ='ODOMETERS Halba'!$G8+'ODOMETERS Halba'!$H8-H7-G7 -> 169 | M8: ='ODOMETERS Halba'!$J8+'ODOMETERS Halba'!$K8+'ODOMETERS Halba'!$L8 -> 1277
A9: 45969 | C9: 40689 | D9: 15226 | E9: 31886 | F9: 8117 | G9: 6615904 | H9: 6417659 | J9: ='ODOMETERS Halba'!$C9+'ODOMETERS Halba'!$D9-D8-C8 -> 1895 | K9: ='ODOMETERS Halba'!$E9+'ODOMETERS Halba'!$F9-F8-E8 -> 1059 | L9: ='ODOMETERS Halba'!$G9+'ODOMETERS Halba'!$H9-H8-G8 -> 434 | M9: ='ODOMETERS Halba'!$J9+'ODOMETERS Halba'!$K9+'ODOMETERS Halba'!$L9 -> 3388
A10: 45970 | C10: 42154 | D10: 15849 | E10: 32384 | F10: 8204 | G10: 6616216 | H10: 6419864 | J10: ='ODOMETERS Halba'!$C10+'ODOMETERS Halba'!$D10-D9-C9 -> 2088 | K10: ='ODOMETERS Halba'!$E10+'ODOMETERS Halba'!$F10-F9-E9 -> 585 | L10: ='ODOMETERS Halba'!$G10+'ODOMETERS Halba'!$H10-H9-G9 -> 2517 | M10: ='ODOMETERS Halba'!$J10+'ODOMETERS Halba'!$K10+'ODOMETERS Halba'!$L10 -> 5190
A11: 45971 | C11: 43690 | D11: 16344 | E11: 32643 | F11: 8373 | G11: 6616645 | H11: 6420075 | J11: ='ODOMETERS Halba'!$C11+'ODOMETERS Halba'!$D11-D10-C10 -> 2031 | K11: ='ODOMETERS Halba'!$E11+'ODOMETERS Halba'!$F11-F10-E10 -> 428 | L11: ='ODOMETERS Halba'!$G11+'ODOMETERS Halba'!$H11-H10-G10 -> 640 | M11: ='ODOMETERS Halba'!$J11+'ODOMETERS Halba'!$K11+'ODOMETERS Halba'!$L11 -> 3099
A12: 45972 | B12: Pre Price | C12: 44370 | D12: 16598 | E12: 33056 | F12: 8425 | G12: 6616910 | H12: 6421136 | J12: ='ODOMETERS Halba'!$C12+'ODOMETERS Halba'!$D12-D11-C11 -> 934 | K12: ='ODOMETERS Halba'!$E12+'ODOMETERS Halba'!$F12-F11-E11 -> 465 | L12: ='ODOMETERS Halba'!$G12+'ODOMETERS Halba'!$H12-H11-G11 -> 1326 | M12: ='ODOMETERS Halba'!$J12+'ODOMETERS Halba'!$K12+'ODOMETERS Halba'!$L12 -> 2725
A13: 45972 | B13: Post Price | C13: 44905 | D13: 16973 | E13: 33549 | F13: 8570 | G13: 6617074 | H13: 6421273 | J13: ='ODOMETERS Halba'!$C13+'ODOMETERS Halba'!$D13-D12-C12 -> 910 | K13: ='ODOMETERS Halba'!$E13+'ODOMETERS Halba'!$F13-F12-E12 -> 638 | L13: ='ODOMETERS Halba'!$G13+'ODOMETERS Halba'!$H13-H12-G12 -> 301 | M13: ='ODOMETERS Halba'!$J13+'ODOMETERS Halba'!$K13+'ODOMETERS Halba'!$L13 -> 1849
A14: 45973 | C14: 45759 | D14: 17378 | E14: 34319 | F14: 8762 | G14: 6617575 | H14: 6421888 | J14: ='ODOMETERS Halba'!$C14+'ODOMETERS Halba'!$D14-D13-C13 -> 1259 | K14: ='ODOMETERS Halba'!$E14+'ODOMETERS Halba'!$F14-F13-E13 -> 962 | L14: ='ODOMETERS Halba'!$G14+'ODOMETERS Halba'!$H14-H13-G13 -> 1116 | M14: ='ODOMETERS Halba'!$J14+'ODOMETERS Halba'!$K14+'ODOMETERS Halba'!$L14 -> 3337
A15: 45974 | C15: 46733 | D15: 17981 | E15: 35149 | F15: 8976 | G15: 6617620 | H15: 6422168 | J15: ='ODOMETERS Halba'!$C15+'ODOMETERS Halba'!$D15-D14-C14 -> 1577 | K15: ='ODOMETERS Halba'!$E15+'ODOMETERS Halba'!$F15-F14-E14 -> 1044 | L15: ='ODOMETERS Halba'!$G15+'ODOMETERS Halba'!$H15-H14-G14 -> 325 | M15: ='ODOMETERS Halba'!$J15+'ODOMETERS Halba'!$K15+'ODOMETERS Halba'!$L15 -> 2946
A16: 45975 | B16: Pre Price | C16: 47053 | D16: 18178 | E16: 35542 | F16: 9054 | G16: 6617763 | H16: 6422312 | J16: ='ODOMETERS Halba'!$C16+'ODOMETERS Halba'!$D16-D15-C15 -> 517 | K16: ='ODOMETERS Halba'!$E16+'ODOMETERS Halba'!$F16-F15-E15 -> 471 | L16: ='ODOMETERS Halba'!$G16+'ODOMETERS Halba'!$H16-H15-G15 -> 287 | M16: ='ODOMETERS Halba'!$J16+'ODOMETERS Halba'!$K16+'ODOMETERS Halba'!$L16 -> 1275
A17: 45975 | B17: Post Price | C17: 47416 | D17: 18466 | E17: 35886 | F17: 9144 | G17: 6618052 | H17: 6422675 | J17: ='ODOMETERS Halba'!$C17+'ODOMETERS Halba'!$D17-D16-C16 -> 651 | K17: ='ODOMETERS Halba'!$E17+'ODOMETERS Halba'!$F17-F16-E16 -> 434 | L17: ='ODOMETERS Halba'!$G17+'ODOMETERS Halba'!$H17-H16-G16 -> 652 | M17: ='ODOMETERS Halba'!$J17+'ODOMETERS Halba'!$K17+'ODOMETERS Halba'!$L17 -> 1737
A18: 45976 | C18: 48582 | D18: 18996 | E18: 36555 | F18: 9295 | G18: 6618245 | H18: 6423216 | J18: ='ODOMETERS Halba'!$C18+'ODOMETERS Halba'!$D18-D17-C17 -> 1696 | K18: ='ODOMETERS Halba'!$E18+'ODOMETERS Halba'!$F18-F17-E17 -> 820 | L18: ='ODOMETERS Halba'!$G18+'ODOMETERS Halba'!$H18-H17-G17 -> 734 | M18: ='ODOMETERS Halba'!$J18+'ODOMETERS Halba'!$K18+'ODOMETERS Halba'!$L18 -> 3250
A19: 45977 | C19: 49927 | D19: 19572 | E19: 37404 | F19: 9414 | G19: 6618393 | H19: 6423455 | J19: ='ODOMETERS Halba'!$C19+'ODOMETERS Halba'!$D19-D18-C18 -> 1921 | K19: ='ODOMETERS Halba'!$E19+'ODOMETERS Halba'!$F19-F18-E18 -> 968 | L19: ='ODOMETERS Halba'!$G19+'ODOMETERS Halba'!$H19-H18-G18 -> 387 | M19: ='ODOMETERS Halba'!$J19+'ODOMETERS Halba'!$K19+'ODOMETERS Halba'!$L19 -> 3276
A20: 45978 | C20: 51096 | D20: 20224 | E20: 38006 | F20: 9694 | G20: 6619323 | H20: 6426286 | J20: ='ODOMETERS Halba'!$C20+'ODOMETERS Halba'!$D20-D19-C19 -> 1821 | K20: ='ODOMETERS Halba'!$E20+'ODOMETERS Halba'!$F20-F19-E19 -> 882 | L20: ='ODOMETERS Halba'!$G20+'ODOMETERS Halba'!$H20-H19-G19 -> 3761 | M20: ='ODOMETERS Halba'!$J20+'ODOMETERS Halba'!$K20+'ODOMETERS Halba'!$L20 -> 6464
A21: 45979 | B21: Pre Price | C21: 51531 | D21: 20589 | E21: 38319 | F21: 9826 | G21: 6619353 | H21: 6426327 | J21: ='ODOMETERS Halba'!$C21+'ODOMETERS Halba'!$D21-D20-C20 -> 800 | K21: ='ODOMETERS Halba'!$E21+'ODOMETERS Halba'!$F21-F20-E20 -> 445 | L21: ='ODOMETERS Halba'!$G21+'ODOMETERS Halba'!$H21-H20-G20 -> 71 | M21: ='ODOMETERS Halba'!$J21+'ODOMETERS Halba'!$K21+'ODOMETERS Halba'!$L21 -> 1316
A22: 45979 | B22: Pro Price | C22: 52121 | D22: 20772 | E22: 38674 | F22: 9877 | G22: 6619706 | H22: 6426617 | J22: ='ODOMETERS Halba'!$C22+'ODOMETERS Halba'!$D22-D21-C21 -> 773 | K22: ='ODOMETERS Halba'!$E22+'ODOMETERS Halba'!$F22-F21-E21 -> 406 | L22: ='ODOMETERS Halba'!$G22+'ODOMETERS Halba'!$H22-H21-G21 -> 643 | M22: ='ODOMETERS Halba'!$J22+'ODOMETERS Halba'!$K22+'ODOMETERS Halba'!$L22 -> 1822
A23: 45980 | C23: 53066 | D23: 21263 | E23: 39753 | F23: 10143 | G23: 6620168 | H23: 6426817 | J23: ='ODOMETERS Halba'!$C23+'ODOMETERS Halba'!$D23-D22-C22 -> 1436 | K23: ='ODOMETERS Halba'!$E23+'ODOMETERS Halba'!$F23-F22-E22 -> 1345 | L23: ='ODOMETERS Halba'!$G23+'ODOMETERS Halba'!$H23-H22-G22 -> 662 | M23: ='ODOMETERS Halba'!$J23+'ODOMETERS Halba'!$K23+'ODOMETERS Halba'!$L23 -> 3443
A24: 45981 | C24: 53912 | D24: 21859 | E24: 40455 | F24: 10339 | G24: 6620870 | H24: 6427051 | J24: ='ODOMETERS Halba'!$C24+'ODOMETERS Halba'!$D24-D23-C23 -> 1442 | K24: ='ODOMETERS Halba'!$E24+'ODOMETERS Halba'!$F24-F23-E23 -> 898 | L24: ='ODOMETERS Halba'!$G24+'ODOMETERS Halba'!$H24-H23-G23 -> 936 | M24: ='ODOMETERS Halba'!$J24+'ODOMETERS Halba'!$K24+'ODOMETERS Halba'!$L24 -> 3276
A25: 45982 | B25: Pre Price | C25: 54369 | D25: 22034 | E25: 40840 | F25: 10451 | G25: 6620915 | H25: 6427194 | J25: ='ODOMETERS Halba'!$C25+'ODOMETERS Halba'!$D25-D24-C24 -> 632 | K25: ='ODOMETERS Halba'!$E25+'ODOMETERS Halba'!$F25-F24-E24 -> 497 | L25: ='ODOMETERS Halba'!$G25+'ODOMETERS Halba'!$H25-H24-G24 -> 188 | M25: ='ODOMETERS Halba'!$J25+'ODOMETERS Halba'!$K25+'ODOMETERS Halba'!$L25 -> 1317
A26: 45982 | B26: Post Price | C26: 55051 | D26: 22179 | E26: 41591 | F26: 10535 | G26: 6621753 | H26: 6427432 | J26: ='ODOMETERS Halba'!$C26+'ODOMETERS Halba'!$D26-D25-C25 -> 827 | K26: ='ODOMETERS Halba'!$E26+'ODOMETERS Halba'!$F26-F25-E25 -> 835 | L26: ='ODOMETERS Halba'!$G26+'ODOMETERS Halba'!$H26-H25-G25 -> 1076 | M26: ='ODOMETERS Halba'!$J26+'ODOMETERS Halba'!$K26+'ODOMETERS Halba'!$L26 -> 2738
A27: 45983 | C27: 56491 | D27: 22631 | E27: 42619 | F27: 10747 | G27: 6622029 | H27: 6428687 | J27: ='ODOMETERS Halba'!$C27+'ODOMETERS Halba'!$D27-D26-C26 -> 1892 | K27: ='ODOMETERS Halba'!$E27+'ODOMETERS Halba'!$F27-F26-E26 -> 1240 | L27: ='ODOMETERS Halba'!$G27+'ODOMETERS Halba'!$H27-H26-G26 -> 1531 | M27: ='ODOMETERS Halba'!$J27+'ODOMETERS Halba'!$K27+'ODOMETERS Halba'!$L27 -> 4663
A28: 45984 | C28: 57740 | D28: 23064 | E28: 43263 | F28: 10874 | G28: 6622142 | H28: 6428820 | J28: ='ODOMETERS Halba'!$C28+'ODOMETERS Halba'!$D28-D27-C27 -> 1682 | K28: ='ODOMETERS Halba'!$E28+'ODOMETERS Halba'!$F28-F27-E27 -> 771 | L28: ='ODOMETERS Halba'!$G28+'ODOMETERS Halba'!$H28-H27-G27 -> 246 | M28: ='ODOMETERS Halba'!$J28+'ODOMETERS Halba'!$K28+'ODOMETERS Halba'!$L28 -> 2699
A29: 45985 | C29: 58778 | D29: 23433 | E29: 43915 | F29: 11191 | G29: 6622458 | H29: 6429709 | J29: ='ODOMETERS Halba'!$C29+'ODOMETERS Halba'!$D29-D28-C28 -> 1407 | K29: ='ODOMETERS Halba'!$E29+'ODOMETERS Halba'!$F29-F28-E28 -> 969 | L29: ='ODOMETERS Halba'!$G29+'ODOMETERS Halba'!$H29-H28-G28 -> 1205 | M29: ='ODOMETERS Halba'!$J29+'ODOMETERS Halba'!$K29+'ODOMETERS Halba'!$L29 -> 3581
A30: 45986 | B30: Pre Price | C30: 59315 | D30: 23757 | E30: 44134 | F30: 11301 | G30: 6622534 | H30: 6429750 | J30: ='ODOMETERS Halba'!$C30+'ODOMETERS Halba'!$D30-D29-C29 -> 861 | K30: ='ODOMETERS Halba'!$E30+'ODOMETERS Halba'!$F30-F29-E29 -> 329 | L30: ='ODOMETERS Halba'!$G30+'ODOMETERS Halba'!$H30-H29-G29 -> 117 | M30: ='ODOMETERS Halba'!$J30+'ODOMETERS Halba'!$K30+'ODOMETERS Halba'!$L30 -> 1307
A31: 45986 | B31: Post Price | C31: 59821 | D31: 24025 | E31: 44548 | F31: 11470 | G31: 6622768 | H31: 6429865 | J31: ='ODOMETERS Halba'!$C31+'ODOMETERS Halba'!$D31-D30-C30 -> 774 | K31: ='ODOMETERS Halba'!$E31+'ODOMETERS Halba'!$F31-F30-E30 -> 583 | L31: ='ODOMETERS Halba'!$G31+'ODOMETERS Halba'!$H31-H30-G30 -> 349 | M31: ='ODOMETERS Halba'!$J31+'ODOMETERS Halba'!$K31+'ODOMETERS Halba'!$L31 -> 1706
A32: 45987 | C32: 60604 | D32: 24383 | E32: 45239 | F32: 11635 | G32: 6623036 | H32: 6430069 | J32: ='ODOMETERS Halba'!$C32+'ODOMETERS Halba'!$D32-D31-C31 -> 1141 | K32: ='ODOMETERS Halba'!$E32+'ODOMETERS Halba'!$F32-F31-E31 -> 856 | L32: ='ODOMETERS Halba'!$G32+'ODOMETERS Halba'!$H32-H31-G31 -> 472 | M32: ='ODOMETERS Halba'!$J32+'ODOMETERS Halba'!$K32+'ODOMETERS Halba'!$L32 -> 2469
A33: 45988 | C33: 61862 | D33: 24824 | E33: 46054 | F33: 11835 | G33: 6623086 | H33: 6430425 | J33: ='ODOMETERS Halba'!$C33+'ODOMETERS Halba'!$D33-D32-C32 -> 1699 | K33: ='ODOMETERS Halba'!$E33+'ODOMETERS Halba'!$F33-F32-E32 -> 1015 | L33: ='ODOMETERS Halba'!$G33+'ODOMETERS Halba'!$H33-H32-G32 -> 406 | M33: ='ODOMETERS Halba'!$J33+'ODOMETERS Halba'!$K33+'ODOMETERS Halba'!$L33 -> 3120
A34: 45989 | C34: 63112 | D34: 25248 | E34: 47214 | F34: 12094 | G34: 6623672 | H34: 6430560 | J34: ='ODOMETERS Halba'!$C34+'ODOMETERS Halba'!$D34-D33-C33 -> 1674 | K34: ='ODOMETERS Halba'!$E34+'ODOMETERS Halba'!$F34-F33-E33 -> 1419 | L34: ='ODOMETERS Halba'!$G34+'ODOMETERS Halba'!$H34-H33-G33 -> 721 | M34: ='ODOMETERS Halba'!$J34+'ODOMETERS Halba'!$K34+'ODOMETERS Halba'!$L34 -> 3814
A35: 45990 | C35: 64457 | D35: 25591 | E35: 48256 | F35: 12251 | G35: 6624057 | H35: 6430767 | J35: ='ODOMETERS Halba'!$C35+'ODOMETERS Halba'!$D35-D34-C34 -> 1688 | K35: ='ODOMETERS Halba'!$E35+'ODOMETERS Halba'!$F35-F34-E34 -> 1199 | L35: ='ODOMETERS Halba'!$G35+'ODOMETERS Halba'!$H35-H34-G34 -> 592 | M35: ='ODOMETERS Halba'!$J35+'ODOMETERS Halba'!$K35+'ODOMETERS Halba'!$L35 -> 3479
A36: 45991 | C36: 65519 | D36: 25969 | E36: 49099 | F36: 12329 | G36: 6624684 | H36: 6430902 | J36: ='ODOMETERS Halba'!$C36+'ODOMETERS Halba'!$D36-D35-C35 -> 1440 | K36: ='ODOMETERS Halba'!$E36+'ODOMETERS Halba'!$F36-F35-E35 -> 921 | L36: ='ODOMETERS Halba'!$G36+'ODOMETERS Halba'!$H36-H35-G35 -> 762 | M36: ='ODOMETERS Halba'!$J36+'ODOMETERS Halba'!$K36+'ODOMETERS Halba'!$L36 -> 3123
A37: 45992 | C37: 66817 | D37: 26228 | E37: 49792 | F37: 12565 | G37: 6624988 | H37: 6434444 | J37: ='ODOMETERS Halba'!$C37+'ODOMETERS Halba'!$D37-D36-C36 -> 1557 | K37: ='ODOMETERS Halba'!$E37+'ODOMETERS Halba'!$F37-F36-E36 -> 929 | L37: ='ODOMETERS Halba'!$G37+'ODOMETERS Halba'!$H37-H36-G36+2091 -> 5937 | M37: ='ODOMETERS Halba'!$J37+'ODOMETERS Halba'!$K37+'ODOMETERS Halba'!$L37 -> 8423
A38: 45993 | C38: 67917 | D38: 26621 | E38: 50680 | F38: 12805 | G38: 6625337 | H38: 6435377 | J38: ='ODOMETERS Halba'!$C38+'ODOMETERS Halba'!$D38-D37-C37 -> 1493 | K38: ='ODOMETERS Halba'!$E38+'ODOMETERS Halba'!$F38-F37-E37 -> 1128 | L38: ='ODOMETERS Halba'!$G38+'ODOMETERS Halba'!$H38-H37-G37 -> 1282 | M38: ='ODOMETERS Halba'!$J38+'ODOMETERS Halba'!$K38+'ODOMETERS Halba'!$L38 -> 3903
A39: 45994 | B39: Pre Price | C39: 68254 | D39: 26720 | E39: 51358 | F39: 13076 | G39: 6625374 | H39: 6436822 | J39: ='ODOMETERS Halba'!$C39+'ODOMETERS Halba'!$D39-D38-C38 -> 436 | K39: ='ODOMETERS Halba'!$E39+'ODOMETERS Halba'!$F39-F38-E38 -> 949 | L39: ='ODOMETERS Halba'!$G39+'ODOMETERS Halba'!$H39-H38-G38 -> 1482 | M39: ='ODOMETERS Halba'!$J39+'ODOMETERS Halba'!$K39+'ODOMETERS Halba'!$L39 -> 2867
A40: 45994 | B40: Post Price | C40: 68589 | D40: 26914 | E40: 51889 | F40: 13283 | G40: 6625820 | H40: 6437106 | J40: ='ODOMETERS Halba'!$C40+'ODOMETERS Halba'!$D40-D39-C39 -> 529 | K40: ='ODOMETERS Halba'!$E40+'ODOMETERS Halba'!$F40-F39-E39 -> 738 | L40: ='ODOMETERS Halba'!$G40+'ODOMETERS Halba'!$H40-H39-G39 -> 730 | M40: ='ODOMETERS Halba'!$J40+'ODOMETERS Halba'!$K40+'ODOMETERS Halba'!$L40 -> 1997
...

Sheet Oil Stock Halba
A4: Item | B4: Price | C4: 9-Feb | D4: 11-Feb | E4: 17-Feb | F4: 20-Feb | G4: 25-Feb | H4: 7-Mar | I4: 23-Mar | J4: 6-Apr | K4: 14-Apr | L4: 28-Jun | M4: Restock | N4: Sold | O4: Value
A5: Shmol 10w-40 | B5: 6.5 | C5: 19 | D5: 18 | E5: 18 | F5: 17 | G5: 16 | H5: 13 | I5: 5 | J5: 3 | K5: 1 | L5: 1 | N5: =Table1[[#This Row],[14-Apr]]-Table1[[#This Row],[28-Jun]]+Table1[[#This Row],[Restock]] -> 0 | O5: =Table1[[#This Row],[Sold]]*Table1[[#This Row],[Price]] -> 0
A6: Shmol 5w-30 | B6: 9 | C6: 13 | D6: 13 | E6: 13 | F6: 13 | G6: 13 | H6: 13 | I6: 13 | J6: 12 | K6: 12 | L6: 12 | N6: =Table1[[#This Row],[14-Apr]]-Table1[[#This Row],[28-Jun]]+Table1[[#This Row],[Restock]] -> 0 | O6: =Table1[[#This Row],[Sold]]*Table1[[#This Row],[Price]] -> 0
A7: Shmol 20w-50 | B7: 8 | C7: 13 | D7: 13 | E7: 13 | F7: 13 | G7: 13 | H7: 12 | I7: 12 | J7: 12 | K7: 12 | L7: 12 | N7: =Table1[[#This Row],[14-Apr]]-Table1[[#This Row],[28-Jun]]+Table1[[#This Row],[Restock]] -> 0 | O7: =Table1[[#This Row],[Sold]]*Table1[[#This Row],[Price]] -> 0
A8: Shmol ATF | B8: 9 | C8: 37 | D8: 37 | E8: 37 | F8: 35 | G8: 35 | H8: =35-6 -> 29 | I8: 31 | J8: 31 | K8: 31 | L8: 31 | N8: =Table1[[#This Row],[14-Apr]]-Table1[[#This Row],[28-Jun]]+Table1[[#This Row],[Restock]] -> 0 | O8: =Table1[[#This Row],[Sold]]*Table1[[#This Row],[Price]] -> 0
N9: =Table1[[#This Row],[14-Apr]]-Table1[[#This Row],[28-Jun]]+Table1[[#This Row],[Restock]] -> 0 | O9: =Table1[[#This Row],[Sold]]*Table1[[#This Row],[Price]] -> 0
A10: Morse | B10: =250/89.7 -> 2.787068 | C10: 30 | D10: 58 | E10: 57 | F10: 57 | G10: 56 | H10: =50-12 -> 38 | I10: 32 | J10: 29 | K10: 26 | L10: 30 | M10: 30 | N10: =Table1[[#This Row],[14-Apr]]-Table1[[#This Row],[28-Jun]]+Table1[[#This Row],[Restock]] -> 26 | O10: =Table1[[#This Row],[Sold]]*Table1[[#This Row],[Price]] -> 72.463768
A11: dot 3 | B11: =150/89.7 -> 1.6722408 | C11: 55 | D11: 55 | E11: 55 | F11: 54 | G11: 54 | H11: =53-12 -> 41 | I11: 38 | J11: 35 | K11: 35 | L11: 20 | N11: =Table1[[#This Row],[14-Apr]]-Table1[[#This Row],[28-Jun]]+Table1[[#This Row],[Restock]] -> 15 | O11: =Table1[[#This Row],[Sold]]*Table1[[#This Row],[Price]] -> 25.083612
N12: =Table1[[#This Row],[14-Apr]]-Table1[[#This Row],[28-Jun]]+Table1[[#This Row],[Restock]] -> 0 | O12: =Table1[[#This Row],[Sold]]*Table1[[#This Row],[Price]] -> 0
N13: =Table1[[#This Row],[14-Apr]]-Table1[[#This Row],[28-Jun]]+Table1[[#This Row],[Restock]] -> 0 | O13: =Table1[[#This Row],[Sold]]*Table1[[#This Row],[Price]] -> 0
A14: Kraft max ATF synthetic white | B14: 8 | C14: 20 | D14: 20 | E14: 19 | F14: 19 | G14: 18 | H14: 18 | I14: 18 | J14: 16 | K14: 16 | L14: 12 | N14: =Table1[[#This Row],[14-Apr]]-Table1[[#This Row],[28-Jun]]+Table1[[#This Row],[Restock]] -> 4 | O14: =Table1[[#This Row],[Sold]]*Table1[[#This Row],[Price]] -> 32
A15: Kraft max ATF red | N15: =Table1[[#This Row],[14-Apr]]-Table1[[#This Row],[28-Jun]]+Table1[[#This Row],[Restock]] -> 0 | O15: =Table1[[#This Row],[Sold]]*Table1[[#This Row],[Price]] -> 0
A16: Kraft max injector cleaner | B16: 5 | C16: 26 | D16: 25 | E16: 25 | F16: 25 | G16: 25 | H16: 22 | I16: 21 | J16: 20 | K16: 19 | L16: 47 | M16: 48 | N16: =Table1[[#This Row],[14-Apr]]-Table1[[#This Row],[28-Jun]]+Table1[[#This Row],[Restock]] -> 20 | O16: =Table1[[#This Row],[Sold]]*Table1[[#This Row],[Price]] -> 100
A17: Kraft max Gasoline plus | N17: =Table1[[#This Row],[14-Apr]]-Table1[[#This Row],[28-Jun]]+Table1[[#This Row],[Restock]] -> 0 | O17: =Table1[[#This Row],[Sold]]*Table1[[#This Row],[Price]] -> 0
N18: =Table1[[#This Row],[14-Apr]]-Table1[[#This Row],[28-Jun]]+Table1[[#This Row],[Restock]] -> 0 | O18: =Table1[[#This Row],[Sold]]*Table1[[#This Row],[Price]] -> 0
A19: Castrol 20w-50 | B19: 6 | C19: 20 | D19: 20 | E19: 20 | F19: 163 | G19: 162 | H19: =162-12 -> 150 | I19: 140 | J19: 139 | K19: 139 | L19: 135 | N19: =Table1[[#This Row],[14-Apr]]-Table1[[#This Row],[28-Jun]]+Table1[[#This Row],[Restock]] -> 4 | O19: =Table1[[#This Row],[Sold]]*Table1[[#This Row],[Price]] -> 24
A20: Castrol 10w-40 | B20: 6 | C20: 27 | D20: 25 | E20: 22 | F20: 164 | G20: 163 | H20: =158-12 -> 146 | I20: 140 | J20: 125 | K20: 121 | L20: 35 | N20: =Table1[[#This Row],[14-Apr]]-Table1[[#This Row],[28-Jun]]+Table1[[#This Row],[Restock]] -> 86 | O20: =Table1[[#This Row],[Sold]]*Table1[[#This Row],[Price]] -> 516
A21: Castrol 5w-30 | B21: 10 | N21: =Table1[[#This Row],[14-Apr]]-Table1[[#This Row],[28-Jun]]+Table1[[#This Row],[Restock]] -> 0 | O21: =Table1[[#This Row],[Sold]]*Table1[[#This Row],[Price]] -> 0
A22: Castrol Mag 5w-30 | B22: 10 | C22: 6 | D22: 6 | E22: 6 | F22: 150 | G22: 150 | H22: =149-12 -> 137 | I22: 137 | J22: 137 | K22: 137 | L22: 122 | N22: =Table1[[#This Row],[14-Apr]]-Table1[[#This Row],[28-Jun]]+Table1[[#This Row],[Restock]] -> 15 | O22: =Table1[[#This Row],[Sold]]*Table1[[#This Row],[Price]] -> 150
A23: Castrol 10w-40 4L | B23: 24 | C23: 6 | D23: 6 | E23: 4 | F23: 4 | G23: 4 | H23: 4 | I23: 4 | J23: 4 | K23: 4 | L23: 4 | N23: =Table1[[#This Row],[14-Apr]]-Table1[[#This Row],[28-Jun]]+Table1[[#This Row],[Restock]] -> 0 | O23: =Table1[[#This Row],[Sold]]*Table1[[#This Row],[Price]] -> 0
A24: Castrol 20w-50 4L | B24: 24 | C24: 4 | D24: 4 | E24: 4 | F24: 4 | G24: 4 | H24: 4 | I24: 4 | J24: 4 | K24: 4 | L24: 4 | N24: =Table1[[#This Row],[14-Apr]]-Table1[[#This Row],[28-Jun]]+Table1[[#This Row],[Restock]] -> 0 | O24: =Table1[[#This Row],[Sold]]*Table1[[#This Row],[Price]] -> 0
A25: Castrol Mag 5w-30 4L | B25: 40 | C25: 2 | D25: 2 | E25: 2 | F25: 2 | G25: 2 | H25: 2 | I25: 2 | J25: 2 | K25: 2 | L25: 2 | N25: =Table1[[#This Row],[14-Apr]]-Table1[[#This Row],[28-Jun]]+Table1[[#This Row],[Restock]] -> 0 | O25: =Table1[[#This Row],[Sold]]*Table1[[#This Row],[Price]] -> 0
A26: Castrol Mag 10w-40 | C26: 0 | D26: 0 | E26: 0 | F26: 144 | G26: 140 | H26: =140-12 -> 128 | I26: 125 | J26: 125 | K26: 118 | L26: 64 | N26: =Table1[[#This Row],[14-Apr]]-Table1[[#This Row],[28-Jun]]+Table1[[#This Row],[Restock]] -> 54 | O26: =Table1[[#This Row],[Sold]]*Table1[[#This Row],[Price]] -> 0
A27: hitek 10w-40 | B27: =300/89.7 -> 3.3444816 | C27: 2 | D27: 37 | E27: 34 | F27: 32 | G27: 31 | H27: 25 | I27: =14+12 -> 26 | J27: 16 | K27: 9 | L27: 24 | M27: 48 | N27: =Table1[[#This Row],[14-Apr]]-Table1[[#This Row],[28-Jun]]+Table1[[#This Row],[Restock]] -> 33 | O27: =Table1[[#This Row],[Sold]]*Table1[[#This Row],[Price]] -> 110.36789
A28: hitek 20w-50 | B28: =300/89.7 -> 3.3444816 | C28: 14 | D28: 14 | E28: 14 | F28: 13 | G28: 11 | H28: 11 | I28: =7+12 -> 19 | J28: 15 | K28: 13 | L28: 21 | M28: 48 | N28: =Table1[[#This Row],[14-Apr]]-Table1[[#This Row],[28-Jun]]+Table1[[#This Row],[Restock]] -> 40 | O28: =Table1[[#This Row],[Sold]]*Table1[[#This Row],[Price]] -> 133.77926
A29: hitek ATF | B29: =300/89.7 -> 3.3444816 | C29: 13 | D29: 12 | E29: 9 | F29: 7 | G29: 5 | H29: 3 | I29: =12 -> 12 | J29: 0 | K29: 0 | L29: 24 | M29: 24 | N29: =Table1[[#This Row],[14-Apr]]-Table1[[#This Row],[28-Jun]]+Table1[[#This Row],[Restock]] -> 0 | O29: =Table1[[#This Row],[Sold]]*Table1[[#This Row],[Price]] -> 0
N30: =Table1[[#This Row],[14-Apr]]-Table1[[#This Row],[28-Jun]]+Table1[[#This Row],[Restock]] -> 0 | O30: =Table1[[#This Row],[Sold]]*Table1[[#This Row],[Price]] -> 0
N31: =Table1[[#This Row],[14-Apr]]-Table1[[#This Row],[28-Jun]]+Table1[[#This Row],[Restock]] -> 0 | O31: =Table1[[#This Row],[Sold]]*Table1[[#This Row],[Price]] -> 0
A32: Max-x 10w-40 | B32: 4 | C32: 0 | D32: 0 | E32: 0 | N32: =Table1[[#This Row],[14-Apr]]-Table1[[#This Row],[28-Jun]]+Table1[[#This Row],[Restock]] -> 0 | O32: =Table1[[#This Row],[Sold]]*Table1[[#This Row],[Price]] -> 0
A33: Max-x 15w-40 | B33: 4 | C33: 9 | D33: 9 | E33: 7 | F33: 7 | G33: 7 | H33: 7 | I33: 4 | J33: 4 | K33: 4 | L33: 0 | N33: =Table1[[#This Row],[14-Apr]]-Table1[[#This Row],[28-Jun]]+Table1[[#This Row],[Restock]] -> 4 | O33: =Table1[[#This Row],[Sold]]*Table1[[#This Row],[Price]] -> 16
